Workbook

Sheet ESTRUTURA_ICOMON
A1: MATR_SAP | B1: RE_* | C1: NOME | D1: SUPERVISOR | E1: COORDENADOR
A2: 80585147 | B2: =IFERROR(A2*1,A2) -> 80585147 | C2: ADRIANO LUIZ DA ALMEIDA SALES | D2: DANILO LEANDRO AVALOS LOPES | E2: WELLINGTON DIAS DA COSTA
A3: 81011080 | B3: =IFERROR(A3*1,A3) -> 81011080 | C3: DAVID MADEIRA | D3: ALEX SILVA SOUSA | E3: DENIS DOS SANTOS
A4: 80165944 | B4: =IFERROR(A4*1,A4) -> 80165944 | C4: JEFFERSON DOS SANTOS PIO | D4: GABRIEL SILVA DIAS | E4: DENIS DOS SANTOS
A5: 80591964 | B5: =IFERROR(A5*1,A5) -> 80591964 | C5: SERGIO MARTINS HIAR JUNIOR | D5: IVAN FERNANDES BATISTA PINHEIRO | E5: WELLINGTON DIAS DA COSTA
A6: 80664035 | B6: =IFERROR(A6*1,A6) -> 80664035 | C6: CLAUDIANO ALVES TEIXEIRA | D6: JOSE ADRIANO LEITE DA SILVA | E6: WELLINGTON DIAS DA COSTA
A7: 80632754 | B7: =IFERROR(A7*1,A7) -> 80632754 | C7: JEFERSON GONCALVES FIGUEIREDO DE JESUS | D7: JOSE ADRIANO LEITE DA SILVA | E7: WELLINGTON DIAS DA COSTA
A8: 80194904 | B8: =IFERROR(A8*1,A8) -> 80194904 | C8: MAURO DOS SANTOS | D8: CLEBERSON MAGALHAES DE LIMA | E8: WELLINGTON DIAS DA COSTA
A9: 80184262 | B9: =IFERROR(A9*1,A9) -> 80184262 | C9: RUBEM MARQUES DA SILVA | D9: ALEXANDRE DE ALENCAR NOVAES | E9: DENIS DOS SANTOS
A10: 80828679 | B10: =IFERROR(A10*1,A10) -> 80828679 | C10: GILBERTO BANDEIRA DA SILVA | D10: FELIPE PEREIRA FEITOSA | E10: DERNIZAN SANTOS MARCIEIRA
A11: 81022579 | B11: =IFERROR(A11*1,A11) -> 81022579 | C11: MATHEUS FONTES SILVA | D11: FELIPE PEREIRA FEITOSA | E11: DERNIZAN SANTOS MARCIEIRA
A12: 80188726 | B12: =IFERROR(A12*1,A12) -> 80188726 | C12: RONILDO ALMEIDA DE SOUZA | D12: FELIPE PEREIRA FEITOSA | E12: DERNIZAN SANTOS MARCIEIRA
A13: 80521921 | B13: =IFERROR(A13*1,A13) -> 80521921 | C13: ANDERSON SOUZA DA SILVA | D13: ADRIANO MENDES DOS SANTOS | E13: DERNIZAN SANTOS MARCIEIRA
... A238: 80972529 | B238: =IFERROR(A238*1,A238) -> 80972529 | C238: VANDERLEI DIOGO DE OLIVEIRA | D238: DANILO LEANDRO AVALOS LOPES | E238: WELLINGTON DIAS DA COSTA

Sheet RIT_ICOMON
A1: ID | B1: DATA | C1: VISTORIADOR | D1: ANO | E1: MÊS | F1: SEMANA
A2: 42775 | B2: 46204 | C2: ANDRE MENDES DE SOUSA | D2: 2026 | E2: 7 | F2: 27
A3: 42772 | B3: 46204 | C3: MARCUS VINICIUS ARAUJO PRUDENTE | D3: 2026 | E3: 7 | F3: 27
A4: 42771 | B4: 46204 | C4: MARCUS VINICIUS ARAUJO PRUDENTE | D4: 2026 | E4: 7 | F4: 27
A5: 42770 | B5: 46204 | C5: AFONSO HENRIQUES MIGUEL MOREIRA | D5: 2026 | E5: 7 | F5: 27
A6: 42769 | B6: 46204 | C6: ARTHUR ROGERIO JERONIMO DA SILVA | D6: 2026 | E6: 7 | F6: 27
A7: 42768 | B7: 46204 | C7: ARTHUR ROGERIO JERONIMO DA SILVA | D7: 2026 | E7: 7 | F7: 27
A8: 42766 | B8: 46204 | C8: AFONSO HENRIQUES MIGUEL MOREIRA | D8: 2026 | E8: 7 | F8: 27
A9: 42765 | B9: 46204 | C9: AFONSO HENRIQUES MIGUEL MOREIRA | D9: 2026 | E9: 7 | F9: 27
A10: 42762 | B10: 46204 | C10: ALEX SILVA SOUSA | D10: 2026 | E10: 7 | F10: 27
A11: 42761 | B11: 46204 | C11: ALEX SILVA SOUSA | D11: 2026 | E11: 7 | F11: 27
A12: 42746 | B12: 46204 | C12: AFONSO HENRIQUES MIGUEL MOREIRA | D12: 2026 | E12: 7 | F12: 27
A13: 42745 | B13: 46204 | C13: DANILO LEANDRO AVALOS LOPES | D13: 2026 | E13: 7 | F13: 27
... A2306: 47867 | B2306: 46323 | C2306: DIEGO MENDONCA SANTOS | D2306: 2026 | E2306: 10 | F2306: 44

Sheet RIT_FUSIONS
A1: ID | B1: DATA | C1: VISTORIADOR | D1: FLAG_NOVO
A2: 47915 | B2: 46323 | C2: JOSE ADRIANO LEITE DA SILVA | D2: =IFERROR(VLOOKUP(RIT_FUSIONS[[#This Row],[ID]],RIT_ACUM!A:A,1,0),"NOVO") -> 47915
A3: 47914 | B3: 46323 | C3: JOSE ADRIANO LEITE DA SILVA | D3: =IFERROR(VLOOKUP(RIT_FUSIONS[[#This Row],[ID]],RIT_ACUM!A:A,1,0),"NOVO") -> 47914
A4: 47913 | B4: 46323 | C4: ADRIANO MENDES DOS SANTOS | D4: =IFERROR(VLOOKUP(RIT_FUSIONS[[#This Row],[ID]],RIT_ACUM!A:A,1,0),"NOVO") -> 47913
A5: 47912 | B5: 46323 | C5: ADRIANO MENDES DOS SANTOS | D5: =IFERROR(VLOOKUP(RIT_FUSIONS[[#This Row],[ID]],RIT_ACUM!A:A,1,0),"NOVO") -> 47912
A6: 47909 | B6: 46323 | C6: CLEBERSON MAGALHAES DE LIMA | D6: =IFERROR(VLOOKUP(RIT_FUSIONS[[#This Row],[ID]],RIT_ACUM!A:A,1,0),"NOVO") -> 47909
A7: 47908 | B7: 46323 | C7: ANDRE MENDES DE SOUSA | D7: =IFERROR(VLOOKUP(RIT_FUSIONS[[#This Row],[ID]],RIT_ACUM!A:A,1,0),"NOVO") -> 47908
A8: 47907 | B8: 46323 | C8: CLEBERSON MAGALHAES DE LIMA | D8: =IFERROR(VLOOKUP(RIT_FUSIONS[[#This Row],[ID]],RIT_ACUM!A:A,1,0),"NOVO") -> 47907
A9: 47906 | B9: 46323 | C9: CLEBERSON MAGALHAES DE LIMA | D9: =IFERROR(VLOOKUP(RIT_FUSIONS[[#This Row],[ID]],RIT_ACUM!A:A,1,0),"NOVO") -> 47906
A10: 47904 | B10: 46323 | C10: DIEGO MENDONCA SANTOS | D10: =IFERROR(VLOOKUP(RIT_FUSIONS[[#This Row],[ID]],RIT_ACUM!A:A,1,0),"NOVO") -> 47904
A11: 47902 | B11: 46323 | C11: MARCUS VINICIUS ARAUJO PRUDENTE | D11: =IFERROR(VLOOKUP(RIT_FUSIONS[[#This Row],[ID]],RIT_ACUM!A:A,1,0),"NOVO") -> 47902
A12: 47901 | B12: 46323 | C12: MARCUS VINICIUS ARAUJO PRUDENTE | D12: =IFERROR(VLOOKUP(RIT_FUSIONS[[#This Row],[ID]],RIT_ACUM!A:A,1,0),"NOVO") -> 47901
A13: 47900 | B13: 46323 | C13: MARCUS VINICIUS ARAUJO PRUDENTE | D13: =IFERROR(VLOOKUP(RIT_FUSIONS[[#This Row],[ID]],RIT_ACUM!A:A,1,0),"NOVO") -> 47900
... A831: 46381 | B831: 46284 | C831: JOSE ADRIANO LEITE DA SILVA | D831: =IFERROR(VLOOKUP(RIT_FUSIONS[[#This Row],[ID]],RIT_ACUM!A:A,1,0),"NOVO") -> 46381

Sheet RIT_ACUM
A1: ID | B1: DATA | C1: VISTORIADOR | D1: MÊS
A2: 42775 | B2: 46204 | C2: ANDRE MENDES DE SOUSA | D2: =MONTH(B2) -> 7
A3: 42772 | B3: 46204 | C3: MARCUS VINICIUS ARAUJO PRUDENTE | D3: =MONTH(B3) -> 7
A4: 42771 | B4: 46204 | C4: MARCUS VINICIUS ARAUJO PRUDENTE | D4: =MONTH(B4) -> 7
A5: 42770 | B5: 46204 | C5: AFONSO HENRIQUES MIGUEL MOREIRA | D5: =MONTH(B5) -> 7
A6: 42769 | B6: 46204 | C6: ARTHUR ROGERIO JERONIMO DA SILVA | D6: =MONTH(B6) -> 7
A7: 42768 | B7: 46204 | C7: ARTHUR ROGERIO JERONIMO DA SILVA | D7: =MONTH(B7) -> 7
A8: 42766 | B8: 46204 | C8: AFONSO HENRIQUES MIGUEL MOREIRA | D8: =MONTH(B8) -> 7
A9: 42765 | B9: 46204 | C9: AFONSO HENRIQUES MIGUEL MOREIRA | D9: =MONTH(B9) -> 7
A10: 42762 | B10: 46204 | C10: ALEX SILVA SOUSA | D10: =MONTH(B10) -> 7
A11: 42761 | B11: 46204 | C11: ALEX SILVA SOUSA | D11: =MONTH(B11) -> 7
A12: 42746 | B12: 46204 | C12: AFONSO HENRIQUES MIGUEL MOREIRA | D12: =MONTH(B12) -> 7
A13: 42745 | B13: 46204 | C13: DANILO LEANDRO AVALOS LOPES | D13: =MONTH(B13) -> 7
... A2306: 47826 | B2306: 46322 | C2306: DIEGO MENDONCA SANTOS | D2306: =MONTH(B2306) -> 10

Sheet CHECK_FUSIONS
A1: ID | B1: DATA | C1: VISTORIADOR | D1: FLAG_NOVO
A2: 7669 | B2: 46323.753 | C2: AFONSO HENRIQUES MIGUEL MOREIRA | D2: =IFERROR(VLOOKUP(_2__Ferramental_AST[[#This Row],[ID]],CHECK_ACUM!A:A,1,0),"NOVO") -> 7669
A3: 7668 | B3: 46323.753 | C3: AFONSO HENRIQUES MIGUEL MOREIRA | D3: =IFERROR(VLOOKUP(_2__Ferramental_AST[[#This Row],[ID]],CHECK_ACUM!A:A,1,0),"NOVO") -> 7668
A4: 7667 | B4: 46323.751 | C4: AFONSO HENRIQUES MIGUEL MOREIRA | D4: =IFERROR(VLOOKUP(_2__Ferramental_AST[[#This Row],[ID]],CHECK_ACUM!A:A,1,0),"NOVO") -> 7667
A5: 7666 | B5: 46323.75 | C5: AFONSO HENRIQUES MIGUEL MOREIRA | D5: =IFERROR(VLOOKUP(_2__Ferramental_AST[[#This Row],[ID]],CHECK_ACUM!A:A,1,0),"NOVO") -> 7666
A6: 7665 | B6: 46323.749 | C6: AFONSO HENRIQUES MIGUEL MOREIRA | D6: =IFERROR(VLOOKUP(_2__Ferramental_AST[[#This Row],[ID]],CHECK_ACUM!A:A,1,0),"NOVO") -> 7665
A7: 7664 | B7: 46323.697 | C7: DIEGO MENDONCA SANTOS | D7: =IFERROR(VLOOKUP(_2__Ferramental_AST[[#This Row],[ID]],CHECK_ACUM!A:A,1,0),"NOVO") -> 7664
A8: 7663 | B8: 46323.618 | C8: DEYVISON BRUNO CUTRIM FERREIRA | D8: =IFERROR(VLOOKUP(_2__Ferramental_AST[[#This Row],[ID]],CHECK_ACUM!A:A,1,0),"NOVO") -> 7663
A9: 7662 | B9: 46323.616 | C9: DEYVISON BRUNO CUTRIM FERREIRA | D9: =IFERROR(VLOOKUP(_2__Ferramental_AST[[#This Row],[ID]],CHECK_ACUM!A:A,1,0),"NOVO") -> 7662
A10: 7661 | B10: 46322.408 | C10: ALEXANDRE MORAIS MEDEIROS DA SILVA | D10: =IFERROR(VLOOKUP(_2__Ferramental_AST[[#This Row],[ID]],CHECK_ACUM!A:A,1,0),"NOVO") -> 7661
A11: 7660 | B11: 46323.399 | C11: DEYVISON BRUNO CUTRIM FERREIRA | D11: =IFERROR(VLOOKUP(_2__Ferramental_AST[[#This Row],[ID]],CHECK_ACUM!A:A,1,0),"NOVO") -> 7660
A12: 7659 | B12: 46323.398 | C12: DEYVISON BRUNO CUTRIM FERREIRA | D12: =IFERROR(VLOOKUP(_2__Ferramental_AST[[#This Row],[ID]],CHECK_ACUM!A:A,1,0),"NOVO") -> 7659
A13: 7658 | B13: 46322.751 | C13: AFONSO HENRIQUES MIGUEL MOREIRA | D13: =IFERROR(VLOOKUP(_2__Ferramental_AST[[#This Row],[ID]],CHECK_ACUM!A:A,1,0),"NOVO") -> 7658
... A204: 7437 | B204: 46286.661 | C204: ANDRE MENDES DE SOUSA | D204: =IFERROR(VLOOKUP(_2__Ferramental_AST[[#This Row],[ID]],CHECK_ACUM!A:A,1,0),"NOVO") -> 7437

Sheet CHECK_ACUM
A1: ID | B1: DATA | C1: VISTORIADOR | D1: MÊS
A2: 6173 | B2: 46147 | C2: EMERSON PINTO BISPO | D2: =MONTH(B2) -> 5
A3: 6170 | B3: 46147 | C3: NILTON CAMPOS DE BARROS | D3: =MONTH(B3) -> 5
A4: 6183 | B4: 46148 | C4: AFONSO HENRIQUES MIGUEL MOREIRA | D4: =MONTH(B4) -> 5
A5: 6182 | B5: 46148 | C5: DENIS REIS | D5: =MONTH(B5) -> 5
A6: 6181 | B6: 46148 | C6: DEYVISON BRUNO CUTRIM FERREIRA | D6: =MONTH(B6) -> 5
A7: 6180 | B7: 46148 | C7: DEYVISON BRUNO CUTRIM FERREIRA | D7: =MONTH(B7) -> 5
A8: 6177 | B8: 46148 | C8: PRISCILA DE MELO SEVILHA ZANDELI | D8: =MONTH(B8) -> 5
A9: 6176 | B9: 46148 | C9: NILTON CAMPOS DE BARROS | D9: =MONTH(B9) -> 5
A10: 6206 | B10: 46149 | C10: CARMINE AVARESE FILHO | D10: =MONTH(B10) -> 5
A11: 6205 | B11: 46149 | C11: CARMINE AVARESE FILHO | D11: =MONTH(B11) -> 5
A12: 6204 | B12: 46149 | C12: CARMINE AVARESE FILHO | D12: =MONTH(B12) -> 5
A13: 6203 | B13: 46149 | C13: DENIS REIS | D13: =MONTH(B13) -> 5
... A872: 7651 | B872: 46322.412 | C872: DEYVISON BRUNO CUTRIM FERREIRA | D872: =MONTH(B872) -> 10

Sheet DEG_REDE
A1: ID | B1: DATA | C1: GESTORES | D1: FLAG_NOVO
A2: 204 | B2: 46150 | C2: Carmine Avarese Filho | D2: =IFERROR(VLOOKUP(DEG_REDE[[#This Row],[ID]],DEG_ACUM!A:A,1,0),"NOVO") -> 204
A3: 205 | B3: 46150 | C3: Carmine Avarese Filho | D3: =IFERROR(VLOOKUP(DEG_REDE[[#This Row],[ID]],DEG_ACUM!A:A,1,0),"NOVO") -> 205
A4: 206 | B4: 46150 | C4: Carmine Avarese Filho | D4: =IFERROR(VLOOKUP(DEG_REDE[[#This Row],[ID]],DEG_ACUM!A:A,1,0),"NOVO") -> 206
A5: 207 | B5: 46150 | C5: Carmine Avarese Filho | D5: =IFERROR(VLOOKUP(DEG_REDE[[#This Row],[ID]],DEG_ACUM!A:A,1,0),"NOVO") -> 207
A6: 208 | B6: 46150 | C6: Carmine Avarese Filho | D6: =IFERROR(VLOOKUP(DEG_REDE[[#This Row],[ID]],DEG_ACUM!A:A,1,0),"NOVO") -> 208
A7: 209 | B7: 46150 | C7: Carmine Avarese Filho | D7: =IFERROR(VLOOKUP(DEG_REDE[[#This Row],[ID]],DEG_ACUM!A:A,1,0),"NOVO") -> 209
A8: 210 | B8: 46150 | C8: Carmine Avarese Filho | D8: =IFERROR(VLOOKUP(DEG_REDE[[#This Row],[ID]],DEG_ACUM!A:A,1,0),"NOVO") -> 210
A9: 211 | B9: 46150 | C9: Carmine Avarese Filho | D9: =IFERROR(VLOOKUP(DEG_REDE[[#This Row],[ID]],DEG_ACUM!A:A,1,0),"NOVO") -> 211
A10: 212 | B10: 46150 | C10: Carmine Avarese Filho | D10: =IFERROR(VLOOKUP(DEG_REDE[[#This Row],[ID]],DEG_ACUM!A:A,1,0),"NOVO") -> 212
A11: 213 | B11: 46150 | C11: Carmine Avarese Filho | D11: =IFERROR(VLOOKUP(DEG_REDE[[#This Row],[ID]],DEG_ACUM!A:A,1,0),"NOVO") -> 213
A12: 214 | B12: 46150 | C12: Carmine Avarese Filho | D12: =IFERROR(VLOOKUP(DEG_REDE[[#This Row],[ID]],DEG_ACUM!A:A,1,0),"NOVO") -> 214
A13: 215 | B13: 46150 | C13: Carmine Avarese Filho | D13: =IFERROR(VLOOKUP(DEG_REDE[[#This Row],[ID]],DEG_ACUM!A:A,1,0),"NOVO") -> 215
... A1369: 3645 | B1369: 46324 | C1369: Andre Mendes De Sousa | D1369: =IFERROR(VLOOKUP(DEG_REDE[[#This Row],[ID]],DEG_ACUM!A:A,1,0),"NOVO") -> 3645

Sheet DEG_ACUM
A1: ID | B1: DATA | C1: VISTORIADOR | D1: MÊS
A2: 25856 | B2: 46024 | C2: MARCIA DOS SANTOS MATSUDA | D2: =MONTH(Tabela6[[#This Row],[DATA]]) -> 1
A3: 25857 | B3: 46024 | C3: MARCIA DOS SANTOS MATSUDA | D3: =MONTH(Tabela6[[#This Row],[DATA]]) -> 1
A4: 25858 | B4: 46024 | C4: MARCIA DOS SANTOS MATSUDA | D4: =MONTH(Tabela6[[#This Row],[DATA]]) -> 1
A5: 25859 | B5: 46024 | C5: MARCIA DOS SANTOS MATSUDA | D5: =MONTH(Tabela6[[#This Row],[DATA]]) -> 1
A6: 25861 | B6: 46027 | C6: DEYVISON BRUNO CUTRIM FERREIRA | D6: =MONTH(Tabela6[[#This Row],[DATA]]) -> 1
A7: 25862 | B7: 46027 | C7: DEYVISON BRUNO CUTRIM FERREIRA | D7: =MONTH(Tabela6[[#This Row],[DATA]]) -> 1
A8: 25863 | B8: 46027 | C8: DEYVISON BRUNO CUTRIM FERREIRA | D8: =MONTH(Tabela6[[#This Row],[DATA]]) -> 1
A9: 25864 | B9: 46027 | C9: DEYVISON BRUNO CUTRIM FERREIRA | D9: =MONTH(Tabela6[[#This Row],[DATA]]) -> 1
A10: 25865 | B10: 46027 | C10: DEYVISON BRUNO CUTRIM FERREIRA | D10: =MONTH(Tabela6[[#This Row],[DATA]]) -> 1
A11: 25866 | B11: 46027 | C11: DEYVISON BRUNO CUTRIM FERREIRA | D11: =MONTH(Tabela6[[#This Row],[DATA]]) -> 1
A12: 25867 | B12: 46027 | C12: EMERSON PINTO BISPO | D12: =MONTH(Tabela6[[#This Row],[DATA]]) -> 1
A13: 25868 | B13: 46027 | C13: EMERSON PINTO BISPO | D13: =MONTH(Tabela6[[#This Row],[DATA]]) -> 1
... A2483: 3645 | B2483: 46324 | C2483: Andre Mendes De Sousa | D2483: =MONTH(Tabela6[[#This Row],[DATA]]) -> 10

Sheet CLEAN-UP_ACUM
A1: ID | B1: DATA | C1: VISTORIADOR | D1: MÊS
A2: 30 | B2: 46028 | C2: DENIS REIS | D2: =MONTH(Tabela9[[#This Row],[DATA]]) -> 1
A3: 30 | B3: 46028 | C3: DENIS REIS | D3: =MONTH(Tabela9[[#This Row],[DATA]]) -> 1
A4: 31 | B4: 46036 | C4: BRUNO ARAUJO DE OLIVEIRA COELHO | D4: =MONTH(Tabela9[[#This Row],[DATA]]) -> 1
A5: 31 | B5: 46036 | C5: BRUNO ARAUJO DE OLIVEIRA COELHO | D5: =MONTH(Tabela9[[#This Row],[DATA]]) -> 1
A6: 32 | B6: 46042 | C6: BRUNO ARAUJO DE OLIVEIRA COELHO | D6: =MONTH(Tabela9[[#This Row],[DATA]]) -> 1
A7: 32 | B7: 46042 | C7: BRUNO ARAUJO DE OLIVEIRA COELHO | D7: =MONTH(Tabela9[[#This Row],[DATA]]) -> 1
A8: 33 | B8: 46055 | C8: BRUNO ARAUJO DE OLIVEIRA COELHO | D8: =MONTH(Tabela9[[#This Row],[DATA]]) -> 2
A9: 33 | B9: 46055 | C9: BRUNO ARAUJO DE OLIVEIRA COELHO | D9: =MONTH(Tabela9[[#This Row],[DATA]]) -> 2
A10: 34 | B10: 46057 | C10: AFONSO HENRIQUES MIGUEL MOREIRA | D10: =MONTH(Tabela9[[#This Row],[DATA]]) -> 2
A11: 34 | B11: 46057 | C11: AFONSO HENRIQUES MIGUEL MOREIRA | D11: =MONTH(Tabela9[[#This Row],[DATA]]) -> 2
A12: 35 | B12: 46065 | C12: BRUNO ARAUJO DE OLIVEIRA COELHO | D12: =MONTH(Tabela9[[#This Row],[DATA]]) -> 2
A13: 35 | B13: 46065 | C13: BRUNO ARAUJO DE OLIVEIRA COELHO | D13: =MONTH(Tabela9[[#This Row],[DATA]]) -> 2
... A242: 164 | B242: 46323 | C242: ALEXANDRE MORAIS MEDEIROS DA SILVA | D242: =MONTH(Tabela9[[#This Row],[DATA]]) -> 10

Sheet FISCALIZAÇÃO
A1: ID | B1: DATA | C1: GESTORES | D1: FLAG_NOVO
A2: 1474 | B2: 46077 | C2: CLEITON TRINDADE | D2: =IFERROR(VLOOKUP(FISCALIZAÇÃO[[#This Row],[ID]],FISC_ACUM!A:A,1,0),"NOVO") -> 1474
A3: 1480 | B3: 46078 | C3: CLEITON TRINDADE | D3: =IFERROR(VLOOKUP(FISCALIZAÇÃO[[#This Row],[ID]],FISC_ACUM!A:A,1,0),"NOVO") -> 1480
A4: 1490 | B4: 46078 | C4: DENIS REIS | D4: =IFERROR(VLOOKUP(FISCALIZAÇÃO[[#This Row],[ID]],FISC_ACUM!A:A,1,0),"NOVO") -> 1490
A5: 1491 | B5: 46078 | C5: DEYVISON BRUNO CUTRIM FERREIRA | D5: =IFERROR(VLOOKUP(FISCALIZAÇÃO[[#This Row],[ID]],FISC_ACUM!A:A,1,0),"NOVO") -> 1491
A6: 1487 | B6: 46078 | C6: DENIS REIS | D6: =IFERROR(VLOOKUP(FISCALIZAÇÃO[[#This Row],[ID]],FISC_ACUM!A:A,1,0),"NOVO") -> 1487
A7: 1488 | B7: 46078 | C7: BRUNO ARAUJO DE OLIVEIRA COELHO | D7: =IFERROR(VLOOKUP(FISCALIZAÇÃO[[#This Row],[ID]],FISC_ACUM!A:A,1,0),"NOVO") -> 1488
A8: 1502 | B8: 46078 | C8: BRUNO ARAUJO DE OLIVEIRA COELHO | D8: =IFERROR(VLOOKUP(FISCALIZAÇÃO[[#This Row],[ID]],FISC_ACUM!A:A,1,0),"NOVO") -> 1502
A9: 1503 | B9: 46078 | C9: BRUNO ARAUJO DE OLIVEIRA COELHO | D9: =IFERROR(VLOOKUP(FISCALIZAÇÃO[[#This Row],[ID]],FISC_ACUM!A:A,1,0),"NOVO") -> 1503
A10: 1504 | B10: 46078 | C10: DEYVISON BRUNO CUTRIM FERREIRA | D10: =IFERROR(VLOOKUP(FISCALIZAÇÃO[[#This Row],[ID]],FISC_ACUM!A:A,1,0),"NOVO") -> 1504
A11: 1505 | B11: 46078 | C11: DEYVISON BRUNO CUTRIM FERREIRA | D11: =IFERROR(VLOOKUP(FISCALIZAÇÃO[[#This Row],[ID]],FISC_ACUM!A:A,1,0),"NOVO") -> 1505
A12: 1506 | B12: 46078 | C12: DEYVISON BRUNO CUTRIM FERREIRA | D12: =IFERROR(VLOOKUP(FISCALIZAÇÃO[[#This Row],[ID]],FISC_ACUM!A:A,1,0),"NOVO") -> 1506
A13: 1511 | B13: 46079 | C13: NILTON CAMPOS DE BARROS | D13: =IFERROR(VLOOKUP(FISCALIZAÇÃO[[#This Row],[ID]],FISC_ACUM!A:A,1,0),"NOVO") -> 1511
... A644: 2659 | B644: 46315 | C644: DIEGO MENDONCA SANTOS | D644: =IFERROR(VLOOKUP(FISCALIZAÇÃO[[#This Row],[ID]],FISC_ACUM!A:A,1,0),"NOVO") -> 2659

Sheet FISC_ACUM
A1: ID | B1: DATA | C1: VISTORIADOR | D1: MÊS
A2: 1474 | B2: 46077 | C2: CLEITON TRINDADE | D2: =MONTH(Tabela12[[#This Row],[DATA]]) -> 2
A3: 1480 | B3: 46078 | C3: CLEITON TRINDADE | D3: =MONTH(Tabela12[[#This Row],[DATA]]) -> 2
A4: 1490 | B4: 46078 | C4: DENIS REIS | D4: =MONTH(Tabela12[[#This Row],[DATA]]) -> 2
A5: 1491 | B5: 46078 | C5: DEYVISON BRUNO CUTRIM FERREIRA | D5: =MONTH(Tabela12[[#This Row],[DATA]]) -> 2
A6: 1487 | B6: 46078 | C6: DENIS REIS | D6: =MONTH(Tabela12[[#This Row],[DATA]]) -> 2
A7: 1488 | B7: 46078 | C7: BRUNO ARAUJO DE OLIVEIRA COELHO | D7: =MONTH(Tabela12[[#This Row],[DATA]]) -> 2
A8: 1502 | B8: 46078 | C8: BRUNO ARAUJO DE OLIVEIRA COELHO | D8: =MONTH(Tabela12[[#This Row],[DATA]]) -> 2
A9: 1503 | B9: 46078 | C9: BRUNO ARAUJO DE OLIVEIRA COELHO | D9: =MONTH(Tabela12[[#This Row],[DATA]]) -> 2
A10: 1504 | B10: 46078 | C10: DEYVISON BRUNO CUTRIM FERREIRA | D10: =MONTH(Tabela12[[#This Row],[DATA]]) -> 2
A11: 1505 | B11: 46078 | C11: DEYVISON BRUNO CUTRIM FERREIRA | D11: =MONTH(Tabela12[[#This Row],[DATA]]) -> 2
A12: 1506 | B12: 46078 | C12: DEYVISON BRUNO CUTRIM FERREIRA | D12: =MONTH(Tabela12[[#This Row],[DATA]]) -> 2
A13: 1511 | B13: 46079 | C13: NILTON CAMPOS DE BARROS | D13: =MONTH(Tabela12[[#This Row],[DATA]]) -> 2
... A644: 2659 | B644: 46315 | C644: DIEGO MENDONCA SANTOS | D644: =MONTH(Tabela12[[#This Row],[DATA]]) -> 10

Sheet SD_7
A1: DATA | B1: GESTORES
A2: 45721 | B2: CLEYTON RODRIGUES
A3: 45729 | B3: ROBERTO DO NASCIMENTO GRAMA
A4: 45734 | B4: CLEYTON RODRIGUES
A5: 45734 | B5: CLEYTON RODRIGUES
A6: 45734 | B6: CLEYTON RODRIGUES
A7: 45734 | B7: CLEYTON RODRIGUES
A8: 45734 | B8: CLEYTON RODRIGUES
A9: 45734 | B9: KAIQUE MARCHIORI
A10: 45734 | B10: MARCIO FREIRE
A11: 45734 | B11: MARCIO FREIRE
A12: 45735 | B12: CLEYTON RODRIGUES
A13: 45735 | B13: CLEYTON RODRIGUES
... A3421: 46323 | B3421: DEYVISON BRUNO CUTRIM FERREIRA

Sheet SD_ACUM
A1: DATA | B1: VISTORIADOR | C1: ANO | D1: MÊS
A2: 46028 | B2: DEYVISON BRUNO CUTRIM FERREIRA | C2: =YEAR(Tabela14[[#This Row],[DATA]]) -> 2026 | D2: =MONTH(Tabela14[[#This Row],[DATA]]) -> 1
A3: 46028 | B3: DEYVISON BRUNO CUTRIM FERREIRA | C3: =YEAR(Tabela14[[#This Row],[DATA]]) -> 2026 | D3: =MONTH(Tabela14[[#This Row],[DATA]]) -> 1
A4: 46035 | B4: DEYVISON BRUNO CUTRIM FERREIRA | C4: =YEAR(Tabela14[[#This Row],[DATA]]) -> 2026 | D4: =MONTH(Tabela14[[#This Row],[DATA]]) -> 1
A5: 46035 | B5: NILTON CAMPOS DE BARROS | C5: =YEAR(Tabela14[[#This Row],[DATA]]) -> 2026 | D5: =MONTH(Tabela14[[#This Row],[DATA]]) -> 1
A6: 46055 | B6: AFONSO HENRIQUES MIGUEL MOREIRA | C6: =YEAR(Tabela14[[#This Row],[DATA]]) -> 2026 | D6: =MONTH(Tabela14[[#This Row],[DATA]]) -> 2
A7: 46055 | B7: AFONSO HENRIQUES MIGUEL MOREIRA | C7: =YEAR(Tabela14[[#This Row],[DATA]]) -> 2026 | D7: =MONTH(Tabela14[[#This Row],[DATA]]) -> 2
A8: 46055 | B8: AFONSO HENRIQUES MIGUEL MOREIRA | C8: =YEAR(Tabela14[[#This Row],[DATA]]) -> 2026 | D8: =MONTH(Tabela14[[#This Row],[DATA]]) -> 2
A9: 46055 | B9: AFONSO HENRIQUES MIGUEL MOREIRA | C9: =YEAR(Tabela14[[#This Row],[DATA]]) -> 2026 | D9: =MONTH(Tabela14[[#This Row],[DATA]]) -> 2
A10: 46055 | B10: AFONSO HENRIQUES MIGUEL MOREIRA | C10: =YEAR(Tabela14[[#This Row],[DATA]]) -> 2026 | D10: =MONTH(Tabela14[[#This Row],[DATA]]) -> 2
A11: 46055 | B11: EMERSON PINTO BISPO | C11: =YEAR(Tabela14[[#This Row],[DATA]]) -> 2026 | D11: =MONTH(Tabela14[[#This Row],[DATA]]) -> 2
A12: 46055 | B12: EMERSON PINTO BISPO | C12: =YEAR(Tabela14[[#This Row],[DATA]]) -> 2026 | D12: =MONTH(Tabela14[[#This Row],[DATA]]) -> 2
A13: 46055 | B13: BRUNO ARAUJO DE OLIVEIRA COELHO | C13: =YEAR(Tabela14[[#This Row],[DATA]]) -> 2026 | D13: =MONTH(Tabela14[[#This Row],[DATA]]) -> 2
... A1476: 46323 | B1476: DEYVISON BRUNO CUTRIM FERREIRA | C1476: =YEAR(Tabela14[[#This Row],[DATA]]) -> 2026 | D1476: =MONTH(Tabela14[[#This Row],[DATA]]) -> 10

Sheet FMO
A1: DATA ENVIO | B1: GESTORES
A2: 45708 | B2: JULIANA YONE DE SOUZA PEREIRA
A3: 45708 | B3: JULIANA YONE DE SOUZA PEREIRA
A4: 45708 | B4: JULIANA YONE DE SOUZA PEREIRA
A5: 45708 | B5: JULIANA YONE DE SOUZA PEREIRA
A6: 46027 | B6: DEYVISON BRUNO CUTRIM FERREIRA
A7: 46030 | B7: THAYNA ELIZABETE GOMES DA SILVA
A8: 46030 | B8: THEOGENES PAULO SESTREM PALOPOLI
A9: 46030 | B9: THEOGENES PAULO SESTREM PALOPOLI
A10: 46030 | B10: RENATA SILVA DE SOUSA
A11: 46030 | B11: THAYNA ELIZABETE GOMES DA SILVA
A12: 46031 | B12: THAYNA ELIZABETE GOMES DA SILVA
A13: 46031 | B13: THEOGENES PAULO SESTREM PALOPOLI
... A526: 46273 | B526: CARMINE AVARESE FILHO
A527: 46273
A528: 46273 | B528: CARMINE AVARESE FILHO
A529: 46273 | B529: CARMINE AVARESE FILHO
A530: 46273 | B530: CARMINE AVARESE FILHO
A531: 46275 | B531: CARMINE AVARESE FILHO
A532: 46275 | B532: ARTHUR GOMES
A533: 46275 | B533: ANDRE MENDES DE SOUSA
A534: 46276 | B534: ALEXANDRE MORAIS MEDEIROS
A535: 46276 | B535: CARMINE AVARESE FILHO
A536: 46276 | B536: CARMINE AVARESE FILHO
A537: 46276 | B537: DEYVISON BRUNO CUTRIM FERREIRA
A538: 46276 | B538: ARTHUR GOMES
A539: 46276 | B539: DEYVISON BRUNO CUTRIM FERREIRA
... A674: 46323 | B674: ARTHUR GOMES

Sheet FMO_ACUM
A1: DATA | B1: VISTORIADOR | C1: MÊS
A2: 45708 | B2: JULIANA YONE DE SOUZA PEREIRA | C2: =MONTH(Tabela16[[#This Row],[DATA]]) -> 2
A3: 45708 | B3: JULIANA YONE DE SOUZA PEREIRA | C3: =MONTH(Tabela16[[#This Row],[DATA]]) -> 2
A4: 45708 | B4: JULIANA YONE DE SOUZA PEREIRA | C4: =MONTH(Tabela16[[#This Row],[DATA]]) -> 2
A5: 45708 | B5: JULIANA YONE DE SOUZA PEREIRA | C5: =MONTH(Tabela16[[#This Row],[DATA]]) -> 2
A6: 46027 | B6: DEYVISON BRUNO CUTRIM FERREIRA | C6: =MONTH(Tabela16[[#This Row],[DATA]]) -> 1
A7: 46030 | B7: THAYNA ELIZABETE GOMES DA SILVA | C7: =MONTH(Tabela16[[#This Row],[DATA]]) -> 1
A8: 46030 | B8: THEOGENES PAULO SESTREM PALOPOLI | C8: =MONTH(Tabela16[[#This Row],[DATA]]) -> 1
A9: 46030 | B9: THEOGENES PAULO SESTREM PALOPOLI | C9: =MONTH(Tabela16[[#This Row],[DATA]]) -> 1
A10: 46030 | B10: RENATA SILVA DE SOUSA | C10: =MONTH(Tabela16[[#This Row],[DATA]]) -> 1
A11: 46030 | B11: THAYNA ELIZABETE GOMES DA SILVA | C11: =MONTH(Tabela16[[#This Row],[DATA]]) -> 1
A12: 46031 | B12: THAYNA ELIZABETE GOMES DA SILVA | C12: =MONTH(Tabela16[[#This Row],[DATA]]) -> 1
A13: 46031 | B13: THEOGENES PAULO SESTREM PALOPOLI | C13: =MONTH(Tabela16[[#This Row],[DATA]]) -> 1
... A526: 46273 | B526: CARMINE AVARESE FILHO | C526: =MONTH(Tabela16[[#This Row],[DATA]]) -> 9
A527: 46273 | C527: =MONTH(Tabela16[[#This Row],[DATA]]) -> 9
A528: 46273 | B528: CARMINE AVARESE FILHO | C528: =MONTH(Tabela16[[#This Row],[DATA]]) -> 9
A529: 46273 | B529: CARMINE AVARESE FILHO | C529: =MONTH(Tabela16[[#This Row],[DATA]]) -> 9
A530: 46273 | B530: CARMINE AVARESE FILHO | C530: =MONTH(Tabela16[[#This Row],[DATA]]) -> 9
A531: 46275 | B531: CARMINE AVARESE FILHO | C531: =MONTH(Tabela16[[#This Row],[DATA]]) -> 9
A532: 46275 | B532: ARTHUR GOMES | C532: =MONTH(Tabela16[[#This Row],[DATA]]) -> 9
A533: 46275 | B533: ANDRE MENDES DE SOUSA | C533: =MONTH(Tabela16[[#This Row],[DATA]]) -> 9
A534: 46276 | B534: ALEXANDRE MORAIS MEDEIROS DA SILVA | C534: =MONTH(Tabela16[[#This Row],[DATA]]) -> 9
A535: 46276 | B535: CARMINE AVARESE FILHO | C535: =MONTH(Tabela16[[#This Row],[DATA]]) -> 9
A536: 46276 | B536: CARMINE AVARESE FILHO | C536: =MONTH(Tabela16[[#This Row],[DATA]]) -> 9
A537: 46276 | B537: DEYVISON BRUNO CUTRIM FERREIRA | C537: =MONTH(Tabela16[[#This Row],[DATA]]) -> 9
A538: 46276 | B538: ARTHUR GOMES | C538: =MONTH(Tabela16[[#This Row],[DATA]]) -> 9
A539: 46276 | B539: DEYVISON BRUNO CUTRIM FERREIRA | C539: =MONTH(Tabela16[[#This Row],[DATA]]) -> 9
... A672: 46323 | B672: ARTHUR GOMES | C672: =MONTH(Tabela16[[#This Row],[DATA]]) -> 10

Sheet LIBERADO COMERCIAL
A1: COD_PREDIO | B1: CLUSTER | C1: TIPO_ID | D1: ESTEIRA | E1: dat_LibComercial | F1: AT | G1: nom_End | H1: val_Numero | I1: CABO | J1: PRIMARIA | K1: CONT | L1: LOCAL /ANDAR | M1: Data visita Gestor | N1: GESTOR | O1: Status | P1: Validação Gestão | Q1: Formalizado | R1: Retorno Implantação | S1: Validado | T1: Pendente | U1: Nok | V1: Acesso Negado | W1: Ano | X1: Semana | Y1: Flag_Mês | Z1: Flag_Dia | AA1: Column27 | AB1: MÊS
A2: 853745 | B2: SP/Paulista-Jardins | C2: ALÍVIO | D2: Liberado Comercial | E2: 46140 | F2: JD | G2: Alameda Casa Branca - lado ímpar | H2: 923 | I2: JDF#10 | J2: 43 | K2: 41-48 | 49-56 | L2: 1° / 6° | M2: 45786 | N2: ANDRE MENDES DE SOUSA | O2: NOK | P2: OK | R2: CORRIGIDO | S2: 1 | T2: 0 | U2: 1 | V2: 0 | W2: 2026 | X2: 18 | Y2: 4 | Z2: 28 | AB2: =MONTH(M2) -> 5
A3: 1502648 | B3: SP/Paulista-Jardins | C3: ALIVIO | D3: Liberado Comercial | E3: 46226 | F3: PA | G3: Avenida Paulista - de 2134 ao fim - lado par | H3: 2202 | I3: PAF#16 | J3: 31 | K3: 1-8 | 9-16 | 17-24 | 25-32 | 33-40 | 41-48 | 49-56 | L3: Galeria | 5° | 7° | M3: 45872 | N3: ANDRE MENDES DE SOUSA | O3: OK | P3: OK | S3: 1 | T3: 0 | U3: 0 | V3: 0 | W3: 2026 | X3: 30 | Y3: 7 | Z3: 23 | AB3: =MONTH(M3) -> 8
A4: 1356392 | B4: SP/Paulista-Jardins | C4: ALÍVIO | D4: Liberado Comercial | E4: 46055 | F4: IB | G4: Rua José Maria Lisboa | H4: 591 | I4: IBF#09 | J4: 19 | K4: 33 - 40 | 41 - 48 | M4: 46057 | N4: PRISCILA DE MELO SEVILHA ZANDELI | O4: OK | P4: Atenuado - Encaminhado E-mail | S4: 0 | T4: 0 | U4: 0 | V4: 0 | W4: 2026 | X4: 6 | Y4: 2 | Z4: 2 | AB4: =MONTH(M4) -> 2
A5: 55753 | B5: SP/Paulista-Jardins | C5: CONECTADOS | D5: Liberado Comercial | E5: 46055 | F5: PD | G5: Rua Gustavo Teixeira | H5: 342 | I5: PDF#01 | J5: 79 | K5: 17-24 | 25 - 32 | 33 - 40 | M5: 46065 | N5: CARMINE AVARESE FILHO | O5: OK | P5: OK | S5: 1 | T5: 0 | U5: 0 | V5: 0 | W5: 2026 | X5: 6 | Y5: 2 | Z5: 2 | AB5: =MONTH(M5) -> 2
A6: 1425699 | B6: SP/Paulista-Jardins | C6: CONECTADOS | D6: Liberado Comercial | E6: 46055 | F6: PD | G6: Rua Capote Valente | H6: 1300 | I6: PDF#08 | J6: 99 | K6: 33-40 | 49-56 | M6: 46065 | N6: CARMINE AVARESE FILHO | O6: NÃO AUTORIZADO | P6: OK | S6: 1 | T6: 0 | U6: 0 | V6: 1 | W6: 2026 | X6: 6 | Y6: 2 | Z6: 2 | AB6: =MONTH(M6) -> 2
A7: 1449656 | B7: SP/Paulista-Jardins | C7: ALÍVIO | D7: Liberado Comercial | E7: 46045 | F7: IB | G7: Rua Bastos Pereira | H7: 55 | I7: IBFH#04 | J7: 89 | K7: 01-08 | 09-16 | 17-24 | 25-32 | 33-40 | 41-48 | 49-56 | 57-64 | M7: 46066 | N7: DENIS REIS | O7: OK | P7: 2 SS com sinal atenuado | S7: 0 | T7: 0 | U7: 0 | V7: 0 | W7: 2026 | X7: 4 | Y7: 1 | Z7: 23 | AB7: =MONTH(M7) -> 2
A8: 1497385 | B8: SP/Paulista-Jardins | C8: ALÍVIO | D8: Liberado Comercial | E8: 46055 | F8: IM | G8: Rua Afonso Braz | H8: 693 | I8: IMFH#05 | J8: 101 | K8: 01 - 08 | M8: 46069 | N8: AFONSO HENRIQUES MIGUEL MOREIRA | O8: OK | P8: PENDENTE | S8: 0 | T8: 1 | U8: 0 | V8: 0 | W8: 2026 | X8: 6 | Y8: 2 | Z8: 2 | AB8: =MONTH(M8) -> 2
A9: 1369405 | B9: SP/Paulista-Jardins | C9: CONECTADOS | D9: Liberado Comercial | E9: 46055 | F9: VM | G9: Rua Machado Bitencourt | H9: 420 | I9: VMFH#12 | J9: 81 | K9: 01 - 64 | M9: 46069 | N9: DEYVISON BRUNO CUTRIM FERREIRA | O9: OK | P9: OK | S9: 1 | T9: 0 | U9: 0 | V9: 0 | W9: 2026 | X9: 6 | Y9: 2 | Z9: 2 | AB9: =MONTH(M9) -> 2
A10: 1369405 | B10: SP/Paulista-Jardins | C10: CONECTADOS | D10: Liberado Comercial | E10: 46055 | F10: VM | G10: Rua Machado Bitencourt | H10: 420 | I10: VMFH#12 | J10: 85 | K10: 01 - 64 | M10: 46069 | N10: DEYVISON BRUNO CUTRIM FERREIRA | O10: OK | P10: OK | S10: 1 | T10: 0 | U10: 0 | V10: 0 | W10: 2026 | X10: 6 | Y10: 2 | Z10: 2 | AB10: =MONTH(M10) -> 2
A11: 1369405 | B11: SP/Paulista-Jardins | C11: CONECTADOS | D11: Liberado Comercial | E11: 46055 | F11: VM | G11: Rua Machado Bitencourt | H11: 420 | I11: VMFH#12 | J11: 83 | K11: 33 - 40 | 41 - 48 | M11: 46069 | N11: DEYVISON BRUNO CUTRIM FERREIRA | O11: OK | P11: OK | S11: 1 | T11: 0 | U11: 0 | V11: 0 | W11: 2026 | X11: 6 | Y11: 2 | Z11: 2 | AB11: =MONTH(M11) -> 2
A12: 1395518 | B12: SP/Paulista-Jardins | C12: CONECTADOS | D12: Liberado Comercial | E12: 46055 | F12: IM | G12: Rua Bueno Brandão | H12: 257 | I12: IMFH#04 | J12: 58 | K12: SS4-6 | M12: 46069 | N12: AFONSO HENRIQUES MIGUEL MOREIRA | O12: NOK | P12: PENDENTE INSTALAÇÃO | S12: 0 | T12: 0 | U12: 1 | V12: 0 | W12: 2026 | X12: 6 | Y12: 2 | Z12: 2 | AB12: =MONTH(M12) -> 2
A13: 1395518 | B13: SP/Paulista-Jardins | C13: CONECTADOS | D13: Liberado Comercial | E13: 46055 | F13: IM | G13: Rua Bueno Brandão | H13: 257 | I13: IMFH#04 | J13: 51 | K13: SS7 - 8 | M13: 46069 | N13: DENIS REIS | O13: NOK | P13: PENDENTE INSTALAÇÃO | S13: 0 | T13: 0 | U13: 1 | V13: 0 | W13: 2026 | X13: 6 | Y13: 2 | Z13: 2 | AB13: =MONTH(M13) -> 2
A14: 1407284 | B14: SP/Paulista-Jardins | C14: CONECTADOS | D14: Liberado Comercial | E14: 46059 | F14: VM | G14: Rua Manuel de Paiva | H14: 128 | I14: VMFH#16 | J14: 47 | K14: 01 - 32 | M14: 46069 | N14: DEYVISON BRUNO CUTRIM FERREIRA | O14: OK | P14: OK | S14: 1 | T14: 0 | U14: 0 | V14: 0 | W14: 2026 | X14: 6 | Y14: 2 | Z14: 6 | AB14: =MONTH(M14) -> 2
A15: 1407284 | B15: SP/Paulista-Jardins | C15: CONECTADOS | D15: Liberado Comercial | E15: 46059 | F15: VM | G15: Rua Manuel de Paiva | H15: 128 | I15: VMFH#16 | J15: 45 | K15: 01 - 64 | M15: 46069 | N15: DEYVISON BRUNO CUTRIM FERREIRA | O15: OK | P15: OK | S15: 1 | T15: 0 | U15: 0 | V15: 0 | W15: 2026 | X15: 6 | Y15: 2 | Z15: 6 | AB15: =MONTH(M15) -> 2
... A19: 1485904 | B19: SP/Paulista-Jardins | C19: CONECTADOS | D19: Liberado Comercial | E19: 46059 | F19: PA | G19: Alameda Santos | H19: 211 | I19: PAFH04 | J19: 114 | K19: 17-24 | M19: 46076 | N19: HUMBERTO DE FARIA COSTA | O19: OK | P19: OK | S19: 1 | T19: 0 | U19: 0 | V19: 0 | W19: 2026 | X19: 6 | Y19: 2 | Z19: 6 | AB19: =MONTH(M19) -> 2
A20: 1422308 | B20: SP/Paulista-Jardins | C20: CONECTADOS | D20: Liberado Comercial | E20: 46064 | F20: PA | G20: Rua Maestro Cardim | H20: 1074 | M20: 46076 | N20: HUMBERTO DE FARIA COSTA | O20: OK | P20: OK | S20: 1 | T20: 0 | U20: 0 | V20: 0 | W20: 2026 | X20: 7 | Y20: 2 | Z20: 11 | AB20: =MONTH(M20) -> 2
A21: 1218659 | B21: SP/Paulista-Jardins | C21: CONECTADOS | D21: Liberado Comercial | E21: 46064 | F21: PA | G21: RUA LEONCIO DE CARVALHO | H21: 201 | M21: 46076 | N21: HUMBERTO DE FARIA COSTA | O21: NÃO AUTORIZADO | P21: OK | S21: 1 | T21: 0 | U21: 0 | V21: 1 | W21: 2026 | X21: 7 | Y21: 2 | Z21: 11 | AB21: =MONTH(M21) -> 2
A22: 1407183 | B22: SP/Paulista-Jardins | C22: CONECTADOS | D22: Liberado Comercial | E22: 46063 | F22: JD | G22: Rua Fradique Coutinho | H22: 262 | I22: JDFH#05 | J22: 27 | K22: 01 - 40 | M22: 46090 | N22: HUMBERTO DE FARIA COSTA | O22: OK | P22: CDOI atenuado | Q22: 46091 | R22: Fora do prazo da garantia | S22: 0 | T22: 0 | U22: 0 | V22: 0 | W22: 2026 | X22: 7 | Y22: 2 | Z22: 10 | AB22: =MONTH(M22) -> 3
A23: 1407183 | B23: SP/Paulista-Jardins | C23: CONECTADOS | D23: Liberado Comercial | E23: 46064 | F23: PI | G23: Rua Fradique Coutinho | H23: 262 | I23: JDFH#05 | J23: 108 | K23: 01 - 64 | M23: 46090 | N23: HUMBERTO DE FARIA COSTA | O23: OK | P23: OK | S23: 1 | T23: 0 | U23: 0 | V23: 0 | W23: 2026 | X23: 7 | Y23: 2 | Z23: 11 | AB23: =MONTH(M23) -> 3
A24: 1106195 | B24: SP/Paulista-Jardins | C24: CONECTADOS | D24: Liberado Comercial | E24: 46059 | F24: JD | G24: Alameda Franca | H24: 895 | I24: JDFH#08 | J24: 97 | K24: 01 - 08 | M24: 46091 | N24: HUMBERTO DE FARIA COSTA | O24: NÃO AUTORIZADO | P24: OK | S24: 1 | T24: 0 | U24: 0 | V24: 1 | W24: 2026 | X24: 6 | Y24: 2 | Z24: 6 | AB24: =MONTH(M24) -> 3
A25: 1497136 | B25: SP/Paulista-Jardins | C25: ALÍVIO | D25: Liberado Comercial | E25: 46059 | F25: JD | G25: Alameda Franca | H25: 1633 | I25: JDFH#09 | J25: 53 | K25: 25 - 48 | M25: 46091 | N25: HUMBERTO DE FARIA COSTA | O25: Ok | P25: OK | S25: 1 | T25: 0 | U25: 0 | V25: 0 | W25: 2026 | X25: 6 | Y25: 2 | Z25: 6 | AB25: =MONTH(M25) -> 3
A26: 37004 | B26: SP/Paulista-Jardins | C26: ALÍVIO | D26: Liberado Comercial | E26: 46055 | F26: JD | G26: Rua Capote Valente | H26: 725 | I26: JDF#06 | J26: 68 | K26: SS3-SS4-SS5 | M26: 46097 | N26: HUMBERTO DE FARIA COSTA | O26: NÃO AUTORIZADO | P26: OK | S26: 1 | T26: 0 | U26: 0 | V26: 1 | W26: 2026 | X26: 6 | Y26: 2 | Z26: 2 | AB26: =MONTH(M26) -> 3
A27: 65280 | B27: SP/Paulista-Jardins | C27: ALÍVIO | D27: Liberado Comercial | E27: 46066 | F27: PI | G27: Rua Cardeal Arcoverde | H27: 1972 | M27: 46097 | N27: HUMBERTO DE FARIA COSTA | O27: Ok | P27: OK | S27: 1 | T27: 0 | U27: 0 | V27: 0 | W27: 2026 | X27: 7 | Y27: 2 | Z27: 13 | AB27: =MONTH(M27) -> 3
A28: 1423862 | B28: SP/Paulista-Jardins | C28: ALÍVIO | D28: Liberado Comercial | E28: 46027 | F28: VM | G28: Rua Borges Lagoa | H28: 933 | I28: VMFH#15 | J28: 35 | K28: 25-32 | M28: 46098 | N28: HUMBERTO DE FARIA COSTA | O28: OK | P28: OK | S28: 1 | T28: 0 | U28: 0 | V28: 0 | W28: 2026 | X28: 2 | Y28: 1 | Z28: 5 | AB28: =MONTH(M28) -> 3
A29: 1497383 | B29: SP/Paulista-Jardins | C29: ALÍVIO | D29: Liberado Comercial | E29: 46055 | F29: VM | G29: Rua Borges Lagoa | H29: 947 | I29: VMFH#15 | J29: 35 | K29: 01 - 08 | M29: 46098 | N29: HUMBERTO DE FARIA COSTA | O29: OK | P29: OK | S29: 1 | T29: 0 | U29: 0 | V29: 0 | W29: 2026 | X29: 6 | Y29: 2 | Z29: 2 | AB29: =MONTH(M29) -> 3
A30: 1432640 | B30: SP/Paulista-Jardins | C30: CONECTADOS | D30: Liberado Comercial | E30: 46055 | F30: VM | G30: Rua Borges Lagoa | H30: 564 | I30: VMFH#12 | J30: 137 | K30: 1-8 | M30: 46098 | N30: HUMBERTO DE FARIA COSTA | O30: OK | P30: OK | S30: 1 | T30: 0 | U30: 0 | V30: 0 | W30: 2026 | X30: 6 | Y30: 2 | Z30: 2 | AB30: =MONTH(M30) -> 3
A31: 1470141 | B31: SP/Paulista-Jardins | C31: CONECTADOS | D31: Liberado Comercial | E31: 46055 | F31: JD | G31: Rua Oscar Freire | H31: 1351 | I31: JDFH#06 | J31: 140 | K31: 41 - 48 | M31: 46099 | N31: HUMBERTO DE FARIA COSTA | O31: OK | P31: OK | S31: 1 | T31: 0 | U31: 0 | V31: 0 | W31: 2026 | X31: 6 | Y31: 2 | Z31: 2 | AB31: =MONTH(M31) -> 3
A32: 1322985 | B32: SP/Paulista-Jardins | C32: CONECTADOS | D32: Liberado Comercial | E32: 46041 | F32: PD | G32: Rua Xerentes | H32: 66 | I32: PDFH#09 | J32: 113 | K32: 49-56 | M32: 46100 | N32: HUMBERTO DE FARIA COSTA | O32: NÃO AUTORIZADO | P32: OK | S32: 1 | T32: 0 | U32: 0 | V32: 1 | W32: 2026 | X32: 4 | Y32: 1 | Z32: 19 | AB32: =MONTH(M32) -> 3
A33: 1497834 | B33: SP/Paulista-Jardins | C33: CONECTADOS | D33: Liberado Comercial | E33: 46059 | F33: VM | G33: Avenida Onze de Junho | H33: 220 | I33: VMFH#12 | J33: 87 | K33: 01- 32 | M33: 46101 | N33: HUMBERTO DE FARIA COSTA | O33: NÃO AUTORIZADO | P33: OK | S33: 1 | T33: 0 | U33: 0 | V33: 1 | W33: 2026 | X33: 6 | Y33: 2 | Z33: 6 | AB33: =MONTH(M33) -> 3
A34: 1497834 | B34: SP/Paulista-Jardins | C34: CONECTADOS | D34: Liberado Comercial | E34: 46059 | F34: VM | G34: Avenida Onze de Junho | H34: 220 | I34: VMFH#12 | J34: 83 | K34: 49 - 56 | 57 - 64 | M34: 46101 | N34: HUMBERTO DE FARIA COSTA | O34: NÃO AUTORIZADO | P34: OK | S34: 1 | T34: 0 | U34: 0 | V34: 1 | W34: 2026 | X34: 6 | Y34: 2 | Z34: 6 | AB34: =MONTH(M34) -> 3
A35: 1453236 | B35: SP/Paulista-Jardins | C35: ALÍVIO | D35: Liberado Comercial | E35: 46091 | F35: PD | G35: Rua Cotoxó | H35: 105 | I35: PDFH#11 | J35: 109 | K35: COMPLETA | L35: N. INFORMADO | M35: 46101 | N35: HUMBERTO DE FARIA COSTA | O35: NÃO AUTORIZADO | P35: OK | S35: 1 | T35: 0 | U35: 0 | V35: 1 | W35: 2026 | X35: 11 | Y35: 3 | Z35: 10 | AB35: =MONTH(M35) -> 3
A36: 1453236 | B36: SP/Paulista-Jardins | C36: ALÍVIO | D36: Liberado Comercial | E36: 46091 | F36: PD | G36: Rua Cotoxó | H36: 105 | I36: PDFH#11 | J36: 110 | K36: COMPLETA | L36: N. INFORMADO | M36: 46101 | N36: HUMBERTO DE FARIA COSTA | O36: NÃO AUTORIZADO | P36: OK | S36: 1 | T36: 0 | U36: 0 | V36: 1 | W36: 2026 | X36: 11 | Y36: 3 | Z36: 10 | AB36: =MONTH(M36) -> 3
A37: 1453236 | B37: SP/Paulista-Jardins | C37: ALÍVIO | D37: Liberado Comercial | E37: 46091 | F37: PD | G37: Rua Cotoxó | H37: 105 | I37: PDFH#11 | J37: 111 | K37: COMPLETA | L37: N. INFORMADO | M37: 46101 | N37: HUMBERTO DE FARIA COSTA | O37: NÃO AUTORIZADO | P37: OK | S37: 1 | T37: 0 | U37: 0 | V37: 1 | W37: 2026 | X37: 11 | Y37: 3 | Z37: 10 | AB37: =MONTH(M37) -> 3
A38: 1463281 | B38: SP/Paulista-Jardins | C38: ALÍVIO | D38: Liberado Comercial | E38: 46092 | F38: VM | G38: Rua Doutor Diogo de Faria | H38: 648 | I38: VMFH#15 | J38: 77 | K38: 01-08 | L38: N. INFORMADO | M38: 46101 | N38: HUMBERTO DE FARIA COSTA | O38: OK | P38: OK | S38: 1 | T38: 0 | U38: 0 | V38: 0 | W38: 2026 | X38: 11 | Y38: 3 | Z38: 11 | AB38: =MONTH(M38) -> 3
A39: 1463366 | B39: SP/Paulista-Jardins | C39: ALÍVIO | D39: Liberado Comercial | E39: 46092 | F39: VM | G39: Rua Doutor Diogo de Faria | H39: 1202 | I39: VMFH#15 | J39: 74 | K39: 33-40 | 41-48 | L39: 9° | M39: 46101 | N39: HUMBERTO DE FARIA COSTA | O39: OK | P39: OK | S39: 1 | T39: 0 | U39: 0 | V39: 0 | W39: 2026 | X39: 11 | Y39: 3 | Z39: 11 | AB39: =MONTH(M39) -> 3
A40: 1463402 | B40: SP/Paulista-Jardins | C40: ALÍVIO | D40: Liberado Comercial | E40: 46093 | F40: VM | G40: Rua Doutor Diogo de Faria | H40: 539 | I40: VMFH#12 | J40: 133 | K40: 01 - 08 | 09 - 16 | 17 - 24 | 25 - 32 | L40: 5°/7° | M40: 46101 | N40: HUMBERTO DE FARIA COSTA | O40: ok | P40: ok | S40: 1 | T40: 0 | U40: 0 | V40: 0 | W40: 2026 | X40: 11 | Y40: 3 | Z40: 12 | AB40: =MONTH(M40) -> 3
A41: 1407194 | B41: SP/Paulista-Jardins | C41: ALÍVIO | D41: Liberado Comercial | E41: 46093 | F41: VM | G41: Rua Doutor Diogo de Faria | H41: 448 | I41: VMFH#15 | J41: 89 | K41: 25-32 | 33-40 | 41-48 | 49-56 | 57-64 | L41: N. INFORMADO | M41: 46101 | N41: HUMBERTO DE FARIA COSTA | O41: OK | P41: OK | S41: 1 | T41: 0 | U41: 0 | V41: 0 | W41: 2026 | X41: 11 | Y41: 3 | Z41: 12 | AB41: =MONTH(M41) -> 3
A42: 1494969 | B42: SP/Paulista-Jardins | C42: ALÍVIO | D42: Liberado Comercial | E42: 46094 | F42: PD | G42: Rua Cláudio | H42: 185 | I42: PDFH#11 | J42: 88 | K42: 41-48 | 49-56 | L42: 7°/14° | M42: 46101 | N42: HUMBERTO DE FARIA COSTA | O42: OK | P42: OK | S42: 1 | T42: 0 | U42: 0 | V42: 0 | W42: 2026 | X42: 11 | Y42: 3 | Z42: 13 | AB42: =MONTH(M42) -> 3
A43: 1494969 | B43: SP/Paulista-Jardins | C43: ALÍVIO | D43: Liberado Comercial | E43: 46094 | F43: PD | G43: Rua Cláudio | H43: 185 | I43: PDFH#11 | J43: 64 | K43: COMPLETA | L43: 3°/5°/7°/9°/11° | M43: 46101 | N43: HUMBERTO DE FARIA COSTA | O43: OK | P43: OK | S43: 1 | T43: 0 | U43: 0 | V43: 0 | W43: 2026 | X43: 11 | Y43: 3 | Z43: 13 | AB43: =MONTH(M43) -> 3
...

Sheet CALENDÁRIO
A1: DATA | B1: DIA_SEM | C1: DU | D1: MÊS | E1: DU_ACUM | G1: DATE (D-1) | H1: DU | I1: IRR SAFRA
A2: 46023 | B2: =UPPER(TEXT(A2,"DDD")) -> QUI | C2: 0 | D2: =MONTH(A2) -> 1 | E2: 0 | G2: =TODAY()-1 -> 46323 | H2: =VLOOKUP(G2,A:E,5,0) -> 19 | I2: 14.5
A3: 46024 | B3: =UPPER(TEXT(A3,"DDD")) -> SEX | C3: 1 | D3: =MONTH(A3) -> 1 | E3: 1
A4: 46025 | B4: =UPPER(TEXT(A4,"DDD")) -> SÁB | C4: 0 | D4: =MONTH(A4) -> 1 | E4: 1
A5: 46026 | B5: =UPPER(TEXT(A5,"DDD")) -> DOM | C5: 0 | D5: =MONTH(A5) -> 1 | E5: 1
A6: 46027 | B6: =UPPER(TEXT(A6,"DDD")) -> SEG | C6: 1 | D6: =MONTH(A6) -> 1 | E6: 2 | G6: ATIVIDADE | H6: META-DIA | I6: COMPROMISSO D-1
A7: 46028 | B7: =UPPER(TEXT(A7,"DDD")) -> TER | C7: 1 | D7: =MONTH(A7) -> 1 | E7: 3 | G7: RIT | H7: 4 | I7: =H7*$H$2 -> 76
A8: 46029 | B8: =UPPER(TEXT(A8,"DDD")) -> QUA | C8: 1 | D8: =MONTH(A8) -> 1 | E8: 4 | G8: CHECKLIST | H8: 2 | I8: =H8*$H$2 -> 38
A9: 46030 | B9: =UPPER(TEXT(A9,"DDD")) -> QUI | C9: 1 | D9: =MONTH(A9) -> 1 | E9: 5 | G9: FALHA DE M.O | H9: - | I9: =I7*I2/100 -> 11.02
A10: 46031 | B10: =UPPER(TEXT(A10,"DDD")) -> SEX | C10: 1 | D10: =MONTH(A10) -> 1 | E10: 6 | G10: DEGRADAÇÃO REDE | H10: 4 | I10: =H10*$H$2 -> 76
A11: 46032 | B11: =UPPER(TEXT(A11,"DDD")) -> SÁB | C11: 0 | D11: =MONTH(A11) -> 1 | E11: 6 | G11: LANLAMENTO SD | H11: 2 | I11: =H11*$H$2 -> 38
A12: 46033 | B12: =UPPER(TEXT(A12,"DDD")) -> DOM | C12: 0 | D12: =MONTH(A12) -> 1 | E12: 6 | G12: CLEAN-UP | H12: 0.5 | I12: =H12*$H$2 -> 9.5
A13: 46034 | B13: =UPPER(TEXT(A13,"DDD")) -> SEG | C13: 1 | D13: =MONTH(A13) -> 1 | E13: 7 | G13: MATERIAL INDEVIDO | H13: 4 | I13: =H13*$H$2 -> 76
A14: 46035 | B14: =UPPER(TEXT(A14,"DDD")) -> TER | C14: 1 | D14: =MONTH(A14) -> 1 | E14: 8 | G14: LIBERADO COMERCIAL | H14: 0 | I14: =H14*$H$2 -> 0
A15: 46036 | B15: =UPPER(TEXT(A15,"DDD")) -> QUA | C15: 1 | D15: =MONTH(A15) -> 1 | E15: 9
A16: 46037 | B16: =UPPER(TEXT(A16,"DDD")) -> QUI | C16: 1 | D16: =MONTH(A16) -> 1 | E16: 10
A17: 46038 | B17: =UPPER(TEXT(A17,"DDD")) -> SEX | C17: 1 | D17: =MONTH(A17) -> 1 | E17: 11
A18: 46039 | B18: =UPPER(TEXT(A18,"DDD")) -> SÁB | C18: 0 | D18: =MONTH(A18) -> 1 | E18: 11
A19: 46040 | B19: =UPPER(TEXT(A19,"DDD")) -> DOM | C19: 0 | D19: =MONTH(A19) -> 1 | E19: 11
A20: 46041 | B20: =UPPER(TEXT(A20,"DDD")) -> SEG | C20: 1 | D20: =MONTH(A20) -> 1 | E20: 12
A21: 46042 | B21: =UPPER(TEXT(A21,"DDD")) -> TER | C21: 1 | D21: =MONTH(A21) -> 1 | E21: 13
A22: 46043 | B22: =UPPER(TEXT(A22,"DDD")) -> QUA | C22: 1 | D22: =MONTH(A22) -> 1 | E22: 14
A23: 46044 | B23: =UPPER(TEXT(A23,"DDD")) -> QUI | C23: 1 | D23: =MONTH(A23) -> 1 | E23: 15
A24: 46045 | B24: =UPPER(TEXT(A24,"DDD")) -> SEX | C24: 1 | D24: =MONTH(A24) -> 1 | E24: 16
A25: 46046 | B25: =UPPER(TEXT(A25,"DDD")) -> SÁB | C25: 0 | D25: =MONTH(A25) -> 1 | E25: 16
A26: 46047 | B26: =UPPER(TEXT(A26,"DDD")) -> DOM | C26: 0 | D26: =MONTH(A26) -> 1 | E26: 16
... A274: 46295 | B274: =UPPER(TEXT(A274,"DDD")) -> QUA | C274: 1 | D274: =MONTH(A274) -> 9 | E274: 21
A275: 46296 | B275: =UPPER(TEXT(A275,"DDD")) -> QUI | C275: 1 | D275: =MONTH(A275) -> 10 | E275: =Tabela5[[#This Row],[DU]] -> 1
A276: 46297 | B276: =UPPER(TEXT(A276,"DDD")) -> SEX | C276: 1 | D276: =MONTH(A276) -> 10 | E276: =Tabela5[[#This Row],[DU]]+E275 -> 2
A277: 46298 | B277: =UPPER(TEXT(A277,"DDD")) -> SÁB | C277: 0 | D277: =MONTH(A277) -> 10 | E277: =Tabela5[[#This Row],[DU]]+E276 -> 2
A278: 46299 | B278: =UPPER(TEXT(A278,"DDD")) -> DOM | C278: 0 | D278: =MONTH(A278) -> 10 | E278: =Tabela5[[#This Row],[DU]]+E277 -> 2
A279: 46300 | B279: =UPPER(TEXT(A279,"DDD")) -> SEG | C279: 1 | D279: =MONTH(A279) -> 10 | E279: =Tabela5[[#This Row],[DU]]+E278 -> 3
A280: 46301 | B280: =UPPER(TEXT(A280,"DDD")) -> TER | C280: 1 | D280: =MONTH(A280) -> 10 | E280: =Tabela5[[#This Row],[DU]]+E279 -> 4
A281: 46302 | B281: =UPPER(TEXT(A281,"DDD")) -> QUA | C281: 1 | D281: =MONTH(A281) -> 10 | E281: =Tabela5[[#This Row],[DU]]+E280 -> 5
A282: 46303 | B282: =UPPER(TEXT(A282,"DDD")) -> QUI | C282: 1 | D282: =MONTH(A282) -> 10 | E282: =Tabela5[[#This Row],[DU]]+E281 -> 6
A283: 46304 | B283: =UPPER(TEXT(A283,"DDD")) -> SEX | C283: 1 | D283: =MONTH(A283) -> 10 | E283: =Tabela5[[#This Row],[DU]]+E282 -> 7
A284: 46305 | B284: =UPPER(TEXT(A284,"DDD")) -> SÁB | C284: 0 | D284: =MONTH(A284) -> 10 | E284: =Tabela5[[#This Row],[DU]]+E283 -> 7
A285: 46306 | B285: =UPPER(TEXT(A285,"DDD")) -> DOM | C285: 0 | D285: =MONTH(A285) -> 10 | E285: =Tabela5[[#This Row],[DU]]+E284 -> 7
A286: 46307 | B286: =UPPER(TEXT(A286,"DDD")) -> SEG | C286: 0 | D286: =MONTH(A286) -> 10 | E286: =Tabela5[[#This Row],[DU]]+E285 -> 7
A287: 46308 | B287: =UPPER(TEXT(A287,"DDD")) -> TER | C287: 1 | D287: =MONTH(A287) -> 10 | E287: =Tabela5[[#This Row],[DU]]+E286 -> 8
...

Sheet Acomp_Modernização
A1: AT | B1: DATA CADASTRO | C1: DATA INICIO | D1: DATA FINAL | E1: Endereço | F1: Número | G1: TIPO | H1: STATUS | I1: Fibras | J1: MÊS | K1: SEMANA | L1: DIA
A2: VM | B2: 46126 | C2: 46135 | D2: 46136 | E2: Professora Carolina Ribeiro | F2: 165 | G2: MODERNIZAÇÃO | H2: SERVIÇO OK | I2: 8 | J2: 4 | K2: 17 | L2: 24
A3: JD | B3: 46134 | C3: 46148 | D3: 46150 | E3: Al Min Rocha de Azevedo | F3: 1388 | G3: MODERNIZAÇÃO | H3: SERVIÇO OK | I3: - | J3: 5 | K3: 19 | L3: 8
A4: VM | B4: 46153 | C4: 46161 | D4: 46162 | E4: DR Nicolau de Sousa Queiros | F4: 863 | G4: MODERNIZAÇÃO/ALÍVIO | H4: SERVIÇO OK | I4: - | J4: 5 | K4: 21 | L4: 20
A5: JD | B5: 46155 | C5: 46167 | D5: 46168 | E5: Francisco Leitão | F5: 486 | G5: MODERNIZAÇÃO/ALÍVIO | H5: SERVIÇO OK | I5: - | J5: 5 | K5: 22 | L5: 26
A6: JD | B6: 46155 | C6: 46169 | D6: 46171 | E6: Bela Cintra | F6: 1714 | G6: MODERNIZAÇÃO/ALÍVIO | H6: SERVIÇO OK | I6: - | J6: 5 | K6: 22 | L6: 29
A7: JD | B7: 46134 | C7: 46175 | D7: 46175 | E7: Rua Augusta | F7: 2445 | G7: MODERNIZAÇÃO | H7: SERVIÇO OK | I7: - | J7: 6 | K7: 23 | L7: 2
A8: PA | B8: 46130 | C8: 46181 | D8: 46182 | E8: Al. Ribeirão preto | F8: 111 | G8: MODERNIZAÇÃO | H8: SERVIÇO OK | I8: - | J8: 6 | K8: 24 | L8: 9
A9: JD | B9: 46155 | C9: 46183 | D9: 46183 | E9: Rua Arruda Alvim | F9: 36 | G9: MODERNIZAÇÃO/ALÍVIO | H9: SERVIÇO OK | I9: - | J9: 6 | K9: 24 | L9: 10
A10: HM | B10: 46142 | C10: 46188 | D10: 46191 | E10: Rua Leopoldo couto de magalhaes | F10: 1400 | G10: MODERNIZAÇÃO | H10: SERVIÇO OK | I10: - | J10: 6 | K10: 25 | L10: 18
A11: JD | B11: 46189 | C11: 46197 | D11: 46198 | E11: Rua Capote Valente | F11: 1181 | G11: MODERNIZAÇÃO/ALÍVIO | H11: SERVIÇO OK | I11: - | J11: 6 | K11: 26 | L11: 25
A12: PA | B12: 46183 | C12: 46198 | D12: 46198 | E12: Maestro Cardim | F12: 1273 | G12: MODERNIZAÇÃO | H12: SERVIÇO OK | I12: 4 | J12: 6 | K12: 26 | L12: 25
A13: VM | B13: 46198 | C13: 46202 | D13: 46202 | E13: Rua Dona Brígida | F13: 359 | G13: MODERNIZAÇÃO | H13: SERVIÇO OK | I13: 8 | J13: 6 | K13: 27 | L13: 29
A14: PA | B14: 46170 | C14: 46202 | D14: 46206 | E14: Av. Nove de julho | F14: 1967 | G14: MODERNIZAÇÃO | H14: SERVIÇO OK | I14: 56 | J14: 6 | K14: 27 | L14: 3
A15: HM | B15: 46203 | C15: 46209 | D15: 46209 | E15: Cojuba | F15: 136 | G15: MODERNIZAÇÃO | H15: SERVIÇO OK | I15: 16 | J15: 7 | K15: 28 | L15: 6
A16: PI | B16: 46192 | C16: 46209 | D16: 46210 | E16: Av Brigadeiro Faria Lima | F16: 2081 | G16: MODERNIZAÇÃO | H16: SERVIÇO OK | I16: 24 | J16: 7 | K16: 28 | L16: 7
A17: JD | B17: 46199 | C17: 46210 | D17: 46211 | E17: Rua da Consolação | F17: 3367 | G17: MODERNIZAÇÃO | H17: SERVIÇO OK | I17: 40 | J17: 7 | K17: 28 | L17: 8
A18: JD | B18: 46203 | C18: 46211 | D18: 46211 | E18: Oscar Freire | F18: 1961 | G18: MODERNIZAÇÃO | H18: SERVIÇO OK | I18: 32 | J18: 7 | K18: 28 | L18: 8
A19: JD | B19: 46205 | C19: 46216 | D19: 46217 | E19: Oscar Freire | F19: 1431 | G19: MODERNIZAÇÃO | H19: SERVIÇO OK | I19: 24 | J19: 7 | K19: 29 | L19: 14
A20: JD | B20: 46199 | C20: 46218 | D20: 46218 | E20: Rua Lisboa | F20: 159 | G20: MODERNIZAÇÃO | H20: SERVIÇO OK | I20: 8 | J20: 7 | K20: 29 | L20: 15
A21: VM | B21: 46205 | C21: 46218 | D21: 46220 | E21: Rua Carlos Petit | F21: 135 | G21: MODERNIZAÇÃO | H21: SERVIÇO OK | I21: 56 | J21: 7 | K21: 29 | L21: 17
A22: VM | B22: 46223 | C22: 46226 | D22: 46226 | E22: Av Prefeito Fábio Prado | F22: 655 | G22: MODERNIZAÇÃO | H22: SERVIÇO OK | I22: 8 | J22: 7 | K22: 30 | L22: 23
A23: IM | B23: 46230 | C23: 46230 | D23: 46231 | E23: Av. são Gabriel | F23: 339 | G23: MODERNIZAÇÃO | H23: SERVIÇO OK | I23: 16 | J23: 7 | K23: 31 | L23: 28
... A126: JD | B126: 46323 | C126: 46379 | D126: 46379 | E126: Rua Francisco Leitão | F126: 235 | G126: MODERNIZAÇÃO | H126: AGENDADO | I126: 16 | J126: 12 | K126: 52 | L126: 23

Sheet Modernização
A1: Data Final | B1: AT | C1: MÊS | D1: SEMANA | E1: STATUS
A2: 46136 | B2: VM | C2: =MONTH(A2) -> 4 | D2: =WEEKNUM(A2) -> 17 | E2: CONCLUÍDO
A3: 46150 | B3: JD | C3: =MONTH(A3) -> 5 | D3: =WEEKNUM(A3) -> 19 | E3: CONCLUÍDO
A4: 46162 | B4: VM | C4: =MONTH(A4) -> 5 | D4: =WEEKNUM(A4) -> 21 | E4: CONCLUÍDO
A5: 46168 | B5: JD | C5: =MONTH(A5) -> 5 | D5: =WEEKNUM(A5) -> 22 | E5: CONCLUÍDO
A6: 46171 | B6: JD | C6: =MONTH(A6) -> 5 | D6: =WEEKNUM(A6) -> 22 | E6: CONCLUÍDO
A7: 46175 | B7: JD | C7: =MONTH(A7) -> 6 | D7: =WEEKNUM(A7) -> 23 | E7: CONCLUÍDO
A8: 46181 | B8: PA | C8: =MONTH(A8) -> 6 | D8: =WEEKNUM(A8) -> 24 | E8: CONCLUÍDO
A9: 46183 | B9: JD | C9: =MONTH(A9) -> 6 | D9: =WEEKNUM(A9) -> 24 | E9: CONCLUÍDO
A10: 46188 | B10: HM | C10: =MONTH(A10) -> 6 | D10: =WEEKNUM(A10) -> 25 | E10: CONCLUÍDO
A11: 46197 | B11: JD | C11: =MONTH(A11) -> 6 | D11: =WEEKNUM(A11) -> 26 | E11: CONCLUÍDO
A12: 46198 | B12: PA | C12: =MONTH(A12) -> 6 | D12: =WEEKNUM(A12) -> 26 | E12: CONCLUÍDO
A13: 46202 | B13: VM | C13: =MONTH(A13) -> 6 | D13: =WEEKNUM(A13) -> 27 | E13: CONCLUÍDO
... A82: 46318 | B82: JD | C82: =MONTH(A82) -> 10 | D82: =WEEKNUM(A82) -> 43 | E82: CONCLUÍDO
